Workbook
Name Dynamiclist: 'Change Request Form'!#REF!:INDEX('Change Request Form'!#REF!,COUNTA('Change Request Form'!#REF!))
Name DynamicListHelper: 'Change Request Form'!#REF!:INDEX('Change Request Form'!#REF!,COUNTA('Change Request Form'!#REF!))
Name FilteredProductNames: 'Change Request Form'!#REF!:'Change Request Form'!#REF!
Name Filterproductnames: 'Change Request Form'!#REF!:'Change Request Form'!#REF!
Name ProductNames: #REF!

Sheet Change Request Form
B6: Change Request for AIM Order Proposals
B8: Please provide the type of change (increase or decrease) to the order proposal, the Restaurant's Current Stock On Hand (in cartons) and the reason for the requested change (from the below options) . You do not need to provide the quantity that the order will be adjusted by, this will be determined by the Restaurant Plannner after reviewing the information you provide below.
B9: Please note: Changes to QTYs of Ops Supplies are not permitted in this form. If ‘Specials’ are required prior to your next Order Proposal, to replenish Manual Items and Ops Supplies, then the Restaurant is accountable for the cost.
B10: Reason for Change
B11: Stock On Hand Variance
B12: Manual Items
B13: Safety Stock
B14: Shelf Life
B15: Usage
B18: Change Request - EXAMPLE AMENDMENT (Below example uses NSW WRINs)
B19: WRIN NUMBER | C19: DESCRIPTION | E19: Reduction Type | F19: Stock On Hand | G19: Select Reason for Change | H19: COMMENT
B20: 11267 | C20: SHAKE MIX 10L NSW | E20: Increase | F20: 4 | G20: Stock On Hand Variance
B21: 6147 | C21: BEEF 4:1 DBL LINER A | E21: Increase | F21: 7.5 | G21: Usage
B24: Submit this form by 8am (AEST), the day after you receive your Order Proposal
C25: RESTAURANT:
C26: RESTAURANT NO:
C27: MANAGERS NAME:
C28: DATE/TIME:
C29: DELIVERY DATE:
I30: Internal Use Only
B31: WRIN NUMBER | C31: DESCRIPTION | E31: Reduction Type | F31: Stock On Hand | G31: Select Reason for Change | H31: COMMENT | I31: Add | J31: Cut | K31: Restaurant Action/Feedback for Restaurant
B32: 112085 | C32: BACON RASHER | N32: Item Look Up
N33: Type part of the product name in yellow box below then press enter
N34: bag
N36: Wrin | O36: Product
N37: {=IFERROR(INDEX('Product List'!$A$2:$A$1002,MATCH(0,IF(1='Product List'!$C$2:$C$1002,COUNTIF('Change Request Form'!$N$36:$N36,'Product List'!$A$2:$A$1002),""),0)),"")} -> 15263011 | O37: =IFERROR(IF(VLOOKUP(N37,'Product List'!A:D,4,FALSE)=1,VLOOKUP(N37,'Product List'!A:B,2,FALSE)&"***",VLOOKUP(N37,'Product List'!A:B,2,FALSE)),"") -> BAG B
N38: {=IFERROR(INDEX('Product List'!$A$2:$A$1002,MATCH(0,IF(1='Product List'!$C$2:$C$1002,COUNTIF('Change Request Form'!$N$36:$N37,'Product List'!$A$2:$A$1002),""),0)),"")} -> 15263000 | O38: =IFERROR(IF(VLOOKUP(N38,'Product List'!A:D,4,FALSE)=1,VLOOKUP(N38,'Product List'!A:B,2,FALSE)&"***",VLOOKUP(N38,'Product List'!A:B,2,FALSE)),"") -> BAG B
N39: {=IFERROR(INDEX('Product List'!$A$2:$A$1002,MATCH(0,IF(1='Product List'!$C$2:$C$1002,COUNTIF('Change Request Form'!$N$36:$N38,'Product List'!$A$2:$A$1002),""),0)),"")} -> 141571 | O39: =IFERROR(IF(VLOOKUP(N39,'Product List'!A:D,4,FALSE)=1,VLOOKUP(N39,'Product List'!A:B,2,FALSE)&"***",VLOOKUP(N39,'Product List'!A:B,2,FALSE)),"") -> BAG BREAKFAST NO 16
N40: {=IFERROR(INDEX('Product List'!$A$2:$A$1002,MATCH(0,IF(1='Product List'!$C$2:$C$1002,COUNTIF('Change Request Form'!$N$36:$N39,'Product List'!$A$2:$A$1002),""),0)),"")} -> 141368 | O40: =IFERROR(IF(VLOOKUP(N40,'Product List'!A:D,4,FALSE)=1,VLOOKUP(N40,'Product List'!A:B,2,FALSE)&"***",VLOOKUP(N40,'Product List'!A:B,2,FALSE)),"") -> BAG BREAKFAST NO 16
N41: {=IFERROR(INDEX('Product List'!$A$2:$A$1002,MATCH(0,IF(1='Product List'!$C$2:$C$1002,COUNTIF('Change Request Form'!$N$36:$N40,'Product List'!$A$2:$A$1002),""),0)),"")} -> 127941 | O41: =IFERROR(IF(VLOOKUP(N41,'Product List'!A:D,4,FALSE)=1,VLOOKUP(N41,'Product List'!A:B,2,FALSE)&"***",VLOOKUP(N41,'Product List'!A:B,2,FALSE)),"") -> BAG FRIES SMALL***
N42: {=IFERROR(INDEX('Product List'!$A$2:$A$1002,MATCH(0,IF(1='Product List'!$C$2:$C$1002,COUNTIF('Change Request Form'!$N$36:$N41,'Product List'!$A$2:$A$1002),""),0)),"")} -> 5429611 | O42: =IFERROR(IF(VLOOKUP(N42,'Product List'!A:D,4,FALSE)=1,VLOOKUP(N42,'Product List'!A:B,2,FALSE)&"***",VLOOKUP(N42,'Product List'!A:B,2,FALSE)),"") -> BAG GENERIC SNACK***
N43: {=IFERROR(INDEX('Product List'!$A$2:$A$1002,MATCH(0,IF(1='Product List'!$C$2:$C$1002,COUNTIF('Change Request Form'!$N$36:$N42,'Product List'!$A$2:$A$1002),""),0)),"")} -> 5429684 | O43: =IFERROR(IF(VLOOKUP(N43,'Product List'!A:D,4,FALSE)=1,VLOOKUP(N43,'Product List'!A:B,2,FALSE)&"***",VLOOKUP(N43,'Product List'!A:B,2,FALSE)),"") -> BAG HASH BROWN***
N44: {=IFERROR(INDEX('Product List'!$A$2:$A$1002,MATCH(0,IF(1='Product List'!$C$2:$C$1002,COUNTIF('Change Request Form'!$N$36:$N43,'Product List'!$A$2:$A$1002),""),0)),"")} -> 5429612 | O44: =IFERROR(IF(VLOOKUP(N44,'Product List'!A:D,4,FALSE)=1,VLOOKUP(N44,'Product List'!A:B,2,FALSE)&"***",VLOOKUP(N44,'Product List'!A:B,2,FALSE)),"") -> BAG HASH BROWN***
N45: {=IFERROR(INDEX('Product List'!$A$2:$A$1002,MATCH(0,IF(1='Product List'!$C$2:$C$1002,COUNTIF('Change Request Form'!$N$36:$N44,'Product List'!$A$2:$A$1002),""),0)),"")} -> 3723350 | O45: =IFERROR(IF(VLOOKUP(N45,'Product List'!A:D,4,FALSE)=1,VLOOKUP(N45,'Product List'!A:B,2,FALSE)&"***",VLOOKUP(N45,'Product List'!A:B,2,FALSE)),"") -> BAG McNUGGET 3 PCE***
N46: {=IFERROR(INDEX('Product List'!$A$2:$A$1002,MATCH(0,IF(1='Product List'!$C$2:$C$1002,COUNTIF('Change Request Form'!$N$36:$N45,'Product List'!$A$2:$A$1002),""),0)),"")} -> 141572 | O46: =IFERROR(IF(VLOOKUP(N46,'Product List'!A:D,4,FALSE)=1,VLOOKUP(N46,'Product List'!A:B,2,FALSE)&"***",VLOOKUP(N46,'Product List'!A:B,2,FALSE)),"") -> BAG MDS D BAG
N47: {=IFERROR(INDEX('Product List'!$A$2:$A$1002,MATCH(0,IF(1='Product List'!$C$2:$C$1002,COUNTIF('Change Request Form'!$N$36:$N46,'Product List'!$A$2:$A$1002),""),0)),"")} -> 141542 | O47: =IFERROR(IF(VLOOKUP(N47,'Product List'!A:D,4,FALSE)=1,VLOOKUP(N47,'Product List'!A:B,2,FALSE)&"***",VLOOKUP(N47,'Product List'!A:B,2,FALSE)),"") -> BAG MDS D BAG
N48: {=IFERROR(INDEX('Product List'!$A$2:$A$1002,MATCH(0,IF(1='Product List'!$C$2:$C$1002,COUNTIF('Change Request Form'!$N$36:$N47,'Product List'!$A$2:$A$1002),""),0)),"")} -> 141574 | O48: =IFERROR(IF(VLOOKUP(N48,'Product List'!A:D,4,FALSE)=1,VLOOKUP(N48,'Product List'!A:B,2,FALSE)&"***",VLOOKUP(N48,'Product List'!A:B,2,FALSE)),"") -> BAG MDS D BAG
... N97: {=IFERROR(INDEX('Product List'!$A$2:$A$1002,MATCH(0,IF(1='Product List'!$C$2:$C$1002,COUNTIF('Change Request Form'!$N$36:$N96,'Product List'!$A$2:$A$1002),""),0)),"")} | O97: =IFERROR(IF(VLOOKUP(N97,'Product List'!A:D,4,FALSE)=1,VLOOKUP(N97,'Product List'!A:B,2,FALSE)&"***",VLOOKUP(N97,'Product List'!A:B,2,FALSE)),"")
C98: x | H98: Total | I98: =SUM(I32:I97) -> 0 | J98: =SUM(J32:J97) -> 0 | N98: {=IFERROR(INDEX('Product List'!$A$2:$A$1002,MATCH(0,IF(1='Product List'!$C$2:$C$1002,COUNTIF('Change Request Form'!$N$36:$N97,'Product List'!$A$2:$A$1002),""),0)),"")} | O98: =IFERROR(IF(VLOOKUP(N98,'Product List'!A:D,4,FALSE)=1,VLOOKUP(N98,'Product List'!A:B,2,FALSE)&"***",VLOOKUP(N98,'Product List'!A:B,2,FALSE)),"")
B99: If you have any questions, please contact your Restaurant Planner. | N99: {=IFERROR(INDEX('Product List'!$A$2:$A$1002,MATCH(0,IF(1='Product List'!$C$2:$C$1002,COUNTIF('Change Request Form'!$N$36:$N98,'Product List'!$A$2:$A$1002),""),0)),"")} | O99: =IFERROR(IF(VLOOKUP(N99,'Product List'!A:D,4,FALSE)=1,VLOOKUP(N99,'Product List'!A:B,2,FALSE)&"***",VLOOKUP(N99,'Product List'!A:B,2,FALSE)),"")
...

Sheet Product List
A1: Wrin | B1: Product Name | C1: search match | D1: 1 cut | G1: Increase
A2: 8549021 | B2: APPLE SLICES | C2: =IF('Change Request Form'!$N$34="",0,COUNTIF(B2,"*"&'Change Request Form'!$N$34&"*")) -> 0 | G2: Decrease
A3: 112085 | B3: BACON RASHER | C3: =IF('Change Request Form'!$N$34="",0,COUNTIF(B3,"*"&'Change Request Form'!$N$34&"*")) -> 0
A4: 15263011 | B4: BAG B | C4: =IF('Change Request Form'!$N$34="",0,COUNTIF(B4,"*"&'Change Request Form'!$N$34&"*")) -> 1
A5: 15263000 | B5: BAG B | C5: =IF('Change Request Form'!$N$34="",0,COUNTIF(B5,"*"&'Change Request Form'!$N$34&"*")) -> 1
A6: 141571 | B6: BAG BREAKFAST NO 16 | C6: =IF('Change Request Form'!$N$34="",0,COUNTIF(B6,"*"&'Change Request Form'!$N$34&"*")) -> 1
A7: 141368 | B7: BAG BREAKFAST NO 16 | C7: =IF('Change Request Form'!$N$34="",0,COUNTIF(B7,"*"&'Change Request Form'!$N$34&"*")) -> 1
A8: 127941 | B8: BAG FRIES SMALL | C8: =IF('Change Request Form'!$N$34="",0,COUNTIF(B8,"*"&'Change Request Form'!$N$34&"*")) -> 1 | D8: 1
A9: 5429611 | B9: BAG GENERIC SNACK | C9: =IF('Change Request Form'!$N$34="",0,COUNTIF(B9,"*"&'Change Request Form'!$N$34&"*")) -> 1 | D9: 1
A10: 5429684 | B10: BAG HASH BROWN | C10: =IF('Change Request Form'!$N$34="",0,COUNTIF(B10,"*"&'Change Request Form'!$N$34&"*")) -> 1 | D10: 1
A11: 5429612 | B11: BAG HASH BROWN | C11: =IF('Change Request Form'!$N$34="",0,COUNTIF(B11,"*"&'Change Request Form'!$N$34&"*")) -> 1 | D11: 1
A12: 3723350 | B12: BAG McNUGGET 3 PCE | C12: =IF('Change Request Form'!$N$34="",0,COUNTIF(B12,"*"&'Change Request Form'!$N$34&"*")) -> 1 | D12: 1
A13: 141572 | B13: BAG MDS D BAG | C13: =IF('Change Request Form'!$N$34="",0,COUNTIF(B13,"*"&'Change Request Form'!$N$34&"*")) -> 1
A14: 141542 | B14: BAG MDS D BAG | C14: =IF('Change Request Form'!$N$34="",0,COUNTIF(B14,"*"&'Change Request Form'!$N$34&"*")) -> 1
A15: 141574 | B15: BAG MDS D BAG | C15: =IF('Change Request Form'!$N$34="",0,COUNTIF(B15,"*"&'Change Request Form'!$N$34&"*")) -> 1
A16: 141538 | B16: BAG MDS D BAG | C16: =IF('Change Request Form'!$N$34="",0,COUNTIF(B16,"*"&'Change Request Form'!$N$34&"*")) -> 1
A17: 14205004 | B17: BAG NO 4 | C17: =IF('Change Request Form'!$N$34="",0,COUNTIF(B17,"*"&'Change Request Form'!$N$34&"*")) -> 1
A18: 6145075 | B18: BAG NO 4 | C18: =IF('Change Request Form'!$N$34="",0,COUNTIF(B18,"*"&'Change Request Form'!$N$34&"*")) -> 1
A19: 6723080 | B19: BAG ONION RINGS | C19: =IF('Change Request Form'!$N$34="",0,COUNTIF(B19,"*"&'Change Request Form'!$N$34&"*")) -> 1
A20: 6723100 | B20: BAG ONION RINGS | C20: =IF('Change Request Form'!$N$34="",0,COUNTIF(B20,"*"&'Change Request Form'!$N$34&"*")) -> 1
A21: 12142001 | B21: BAG PASTRY UNPRINTED B987P0330 | C21: =IF('Change Request Form'!$N$34="",0,COUNTIF(B21,"*"&'Change Request Form'!$N$34&"*")) -> 1
A22: 6358100 | B22: BAG PINEAPPLE FRITTER | C22: =IF('Change Request Form'!$N$34="",0,COUNTIF(B22,"*"&'Change Request Form'!$N$34&"*")) -> 1 | D22: 1
A23: 258102 | B23: BASE BREAKFAST | C23: =IF('Change Request Form'!$N$34="",0,COUNTIF(B23,"*"&'Change Request Form'!$N$34&"*")) -> 0
A24: 5059 | B24: BEEF PATTIES 10:1 | C24: =IF('Change Request Form'!$N$34="",0,COUNTIF(B24,"*"&'Change Request Form'!$N$34&"*")) -> 0
A25: 5399 | B25: BEEF PATTIES 10:1 | C25: =IF('Change Request Form'!$N$34="",0,COUNTIF(B25,"*"&'Change Request Form'!$N$34&"*")) -> 0
A26: 5052 | B26: BEEF PATTIES 10:1 | C26: =IF('Change Request Form'!$N$34="",0,COUNTIF(B26,"*"&'Change Request Form'!$N$34&"*")) -> 0
A27: 5875066 | B27: BEEF PATTIES 3:1 | C27: =IF('Change Request Form'!$N$34="",0,COUNTIF(B27,"*"&'Change Request Form'!$N$34&"*")) -> 0
A28: 5875100 | B28: BEEF PATTIES 3:1 | C28: =IF('Change Request Form'!$N$34="",0,COUNTIF(B28,"*"&'Change Request Form'!$N$34&"*")) -> 0
A29: 5875021 | B29: BEEF PATTIES 3:1 | C29: =IF('Change Request Form'!$N$34="",0,COUNTIF(B29,"*"&'Change Request Form'!$N$34&"*")) -> 0
A30: 6085 | B30: BEEF PATTIES 4:1 | C30: =IF('Change Request Form'!$N$34="",0,COUNTIF(B30,"*"&'Change Request Form'!$N$34&"*")) -> 0
A31: 6291 | B31: BEEF PATTIES 4:1 | C31: =IF('Change Request Form'!$N$34="",0,COUNTIF(B31,"*"&'Change Request Form'!$N$34&"*")) -> 0
A32: 6147 | B32: BEEF PATTIES 4:1 | C32: =IF('Change Request Form'!$N$34="",0,COUNTIF(B32,"*"&'Change Request Form'!$N$34&"*")) -> 0
A33: 6766046 | B33: BEEF SAUSAGE PATTIES | C33: =IF('Change Request Form'!$N$34="",0,COUNTIF(B33,"*"&'Change Request Form'!$N$34&"*")) -> 0
A34: 6766043 | B34: BEEF SAUSAGE PATTIES | C34: =IF('Change Request Form'!$N$34="",0,COUNTIF(B34,"*"&'Change Request Form'!$N$34&"*")) -> 0
... A44: 5582228 | B44: BOX McNUGGET 10 PCE | C44: =IF('Change Request Form'!$N$34="",0,COUNTIF(B44,"*"&'Change Request Form'!$N$34&"*")) -> 0
A45: 5582248 | B45: BOX McNUGGET 10 PCE SPICY | C45: =IF('Change Request Form'!$N$34="",0,COUNTIF(B45,"*"&'Change Request Form'!$N$34&"*")) -> 0 | D45: 1
A46: 10638021 | B46: BOX McNUGGET 20 PCE | C46: =IF('Change Request Form'!$N$34="",0,COUNTIF(B46,"*"&'Change Request Form'!$N$34&"*")) -> 0
A47: 5582249 | B47: BOX McNUGGET 20 PCE | C47: =IF('Change Request Form'!$N$34="",0,COUNTIF(B47,"*"&'Change Request Form'!$N$34&"*")) -> 0
A48: 289568 | B48: BOX McNUGGET 20 PCE SPICY | C48: =IF('Change Request Form'!$N$34="",0,COUNTIF(B48,"*"&'Change Request Form'!$N$34&"*")) -> 0 | D48: 1
A49: 10638023 | B49: BOX McNUGGET 24 PCE | C49: =IF('Change Request Form'!$N$34="",0,COUNTIF(B49,"*"&'Change Request Form'!$N$34&"*")) -> 0 | D49: 1
...
